<?xml version="1.0" ?>
<robot name="door">
  <link name="world"/>

  <joint name="finger_to_world" type="prismatic">
    <parent link="world"/>
    <child link="finger1"/>
    <origin xyz="0.5 0.45 0.5" rpy="0 0 0" />
    <axis
      xyz="0 1 0" />
    <limit
      lower="-3.0"
      upper="3.0"
      effort="0"
      velocity="10.0" />
  </joint>

  <link name="finger1">
    <inertial>
       <origin rpy="0 0 0" xyz="0 0 0"/>
       <mass value="1.0"/>
       <inertia ixx="1.0" ixy="0" ixz="0" iyy="1.0" iyz="0" izz="1.0"/>
    </inertial>
    <visual>
      <origin rpy="0 0 0" xyz="0 0 0"/>
      <geometry> <mesh filename="finger.obj" scale="1.0 1.0 1.0"/> </geometry>
      <material name="black"> <color rgba="0.2 0.2 0.2 1.0"/> </material>
    </visual>
    <collision>
      <origin rpy="0 0 0" xyz="0 0 0"/>
      <geometry> <mesh filename="finger.obj" scale="1.0 1.0 1.0"/> </geometry>
    </collision>
  </link>
  
</robot>
